<?xml version="1.0" ?>
<!-- =================================================================================== -->
<!-- |    This document was autogenerated by xacro from phantomx_turtlebot_ensemble.xacro | -->
<!-- |    EDITING THIS FILE BY HAND IS NOT RECOMMENDED                                 | -->
<!-- =================================================================================== -->
<!--

-->
<robot name="turtlebot" xmlns:controller="http://playerstage.sourceforge.net/gazebo/xmlschema/#controller" xmlns:interface="http://playerstage.sourceforge.net/gazebo/xmlschema/#interface" xmlns:sensor="http://playerstage.sourceforge.net/gazebo/xmlschema/#sensor" xmlns:xacro="http://www.ros.org/wiki/xacro">
  <gazebo reference="laser">
    <sensor name="head_hokuyo_sensor" type="ray">
      <pose>0 0 0 0 0 0</pose>
      <visualize>false</visualize>
      <update_rate>10</update_rate>
      <ray>
        <scan>
          <horizontal>
            <samples>360</samples>
            <resolution>1</resolution>
            <min_angle>-1.570796</min_angle>
            <max_angle>1.570796</max_angle>
          </horizontal>
        </scan>
        <range>
          <min>0.10</min>
          <max>30.0</max>
          <resolution>0.01</resolution>
        </range>
        <noise>
          <type>gaussian</type>
          <mean>0.0</mean>
          <stddev>0.01</stddev>
        </noise>
      </ray>
      <plugin filename="libgazebo_ros_laser.so" name="gazebo_ros_head_hokuyo_controller">
        <topicName>/scan</topicName>
        <frameName>laser</frameName>
      </plugin>
    </sensor>
  </gazebo>
  <gazebo>
    <plugin filename="libWifibotController.so" name="turtlebot_controller">
      <alwaysOn>true</alwaysOn>
      <updateRate>100.0</updateRate>
      <topicName>mobile_base/commands/velocity</topicName>
    </plugin>
  </gazebo>
  <gazebo>
    <plugin filename="libgazebo_ros_control.so" name="gazebo_ros_control">
      <robotParam>/robot_description</robotParam>
    </plugin>
  </gazebo>
  <gazebo>
    <plugin filename="libjoint_state_controller.so" name="gazebo_joint_states_publisher">
      <update_rate>1000.0</update_rate>
    </plugin>
  </gazebo>
  <gazebo reference="link1">
    <material>Gazebo/Black</material>
  </gazebo>
  <gazebo reference="link2">
    <mu1>0.2</mu1>
    <mu2>0.2</mu2>
    <material>Gazebo/Orange</material>
  </gazebo>
  <gazebo reference="link3">
    <mu1>0.2</mu1>
    <mu2>0.2</mu2>
    <material>Gazebo/Green</material>
  </gazebo>
  <gazebo reference="link4">
    <mu1>0.2</mu1>
    <mu2>0.2</mu2>
    <material>Gazebo/Orange</material>
  </gazebo>
  <gazebo reference="link5">
    <mu1>0.2</mu1>
    <mu2>0.2</mu2>
    <material>Gazebo/Blue</material>
  </gazebo>
  <gazebo reference="link6">
    <mu1>0.2</mu1>
    <mu2>0.2</mu2>
    <material>Gazebo/Orange</material>
  </gazebo>
  <gazebo reference="camera_link">
    <mu1>0.2</mu1>
    <mu2>0.2</mu2>
    <material>Gazebo/Red</material>
  </gazebo>
  <gazebo reference="finger1_link">
    <mu1>0.9</mu1>
    <mu2>0.9</mu2>
    <material>Gazebo/Green</material>
  </gazebo>
  <gazebo reference="finger2_link">
    <mu1>0.9</mu1>
    <mu2>0.9</mu2>
    <material>Gazebo/Green</material>
  </gazebo>
  <material name="black">
    <color rgba="0.15 0.15 0.15 1.0"/>
  </material>
  <material name="blue">
    <color rgba="0.0 0.0 0.8 1.0"/>
  </material>
  <material name="green">
    <color rgba="0.0 0.8 0.0 1.0"/>
  </material>
  <material name="grey">
    <color rgba="0.2 0.2 0.2 1.0"/>
  </material>
  <material name="orange">
    <color rgba="1.0 0.423529411765 0.0392156862745 1.0"/>
  </material>
  <material name="brown">
    <color rgba="0.870588235294 0.811764705882 0.764705882353 1.0"/>
  </material>
  <material name="red">
    <color rgba="0.8 0.0 0.0 1.0"/>
  </material>
  <material name="white">
    <color rgba="1.0 1.0 1.0 1.0"/>
  </material>
  <joint name="fixed" type="fixed">
    <origin rpy="0 0 0" xyz="0.05 0.0 0.4"/>
    <parent link="base_link"/>
    <child link="link1"/>
  </joint>
  <link name="link1">
    <collision>
      <origin rpy="-0.0 0  -0.0" xyz="-0.1 -0.135 0.0"/>
      <geometry>
        <mesh filename="package://phantomx_description/meshes/Base.stl" scale="0.01 0.01 0.01"/>
      </geometry>
    </collision>
    <visual>
      <origin rpy="-0.0 0  -0.0" xyz="-0.1 -0.135 0.0"/>
      <geometry>
        <mesh filename="package://phantomx_description/meshes/Base.stl" scale="0.01 0.01 0.01"/>
      </geometry>
      <material name="black"/>
    </visual>
    <inertial>
      <origin rpy="0 0 0" xyz="0 0 0"/>
      <mass value="0.1"/>
      <inertia ixx="0.1" ixy="0.0" ixz="0.0" iyy="0.1" iyz="0.0" izz="0.1"/>
    </inertial>
  </link>
  <joint name="arm_shoulder_pan_joint" type="revolute">
    <parent link="link1"/>
    <child link="link2"/>
    <origin rpy="0 0 0" xyz="0 0. 0.086"/>
    <limit effort="10.0" lower="-3.1415926" upper="3.1415926" velocity="2"/>
    <axis xyz="0 0 1"/>
    <dynamics damping="0.7"/>
  </joint>
  <link name="link2">
    <collision>
      <origin rpy="1.5707963 0  0.0" xyz="-0.0 -0.0 0.0"/>
      <geometry>
        <mesh filename="package://phantomx_description/meshes/Shoulder.stl" scale="0.01 0.01 0.01"/>
      </geometry>
      <material name="black"/>
    </collision>
    <visual>
      <origin rpy="1.5707963 0  0.0" xyz="-0.0 -0.0 0.0"/>
      <geometry>
        <mesh filename="package://phantomx_description/meshes/Shoulder.stl" scale="0.01 0.01 0.01"/>
      </geometry>
      <material name="black"/>
    </visual>
    <inertial>
      <origin rpy="0 0 0" xyz="0 0 0"/>
      <mass value="0.1"/>
      <inertia ixx="0.1" ixy="0.0" ixz="0.0" iyy="0.1" iyz="0.0" izz="0.1"/>
    </inertial>
  </link>
  <joint name="arm_shoulder_lift_joint" type="revolute">
    <parent link="link2"/>
    <child link="link3"/>
    <origin rpy="0 0 0" xyz="0 0. 0.042"/>
    <limit effort="10.0" lower="-2.35619445" upper="2.35619445" velocity="2"/>
    <axis xyz="0 1 0"/>
    <dynamics damping="0.7"/>
  </joint>
  <link name="link3">
    <collision>
      <origin rpy="1.5707963 0  0.0" xyz="-0.0 -0.0 0.0"/>
      <geometry>
        <mesh filename="package://phantomx_description/meshes/Bicep.stl" scale="0.01 0.01 0.01"/>
      </geometry>
    </collision>
    <visual>
      <origin rpy="1.5707963 0  0.0" xyz="-0.0 -0.0 0.0"/>
      <geometry>
        <mesh filename="package://phantomx_description/meshes/Bicep.stl" scale="0.01 0.01 0.01"/>
      </geometry>
      <material name="black"/>
    </visual>
    <inertial>
      <origin rpy="0 0 0" xyz="0 0 0"/>
      <mass value="0.1"/>
      <inertia ixx="0.1" ixy="0.0" ixz="0.0" iyy="0.1" iyz="0.0" izz="0.1"/>
    </inertial>
  </link>
  <joint name="arm_elbow_flex_joint" type="revolute">
    <parent link="link3"/>
    <child link="link4"/>
    <origin rpy="0 0 0" xyz="0 0. 0.106"/>
    <limit effort="10.0" lower="-2.51327408" upper="2.51327408" velocity="2"/>
    <axis xyz="0 1 0"/>
    <dynamics damping="0.7"/>
  </joint>
  <link name="link4">
    <collision>
      <origin rpy="1.5707963 0  0.0" xyz="-0.0 -0.0 0.0"/>
      <geometry>
        <mesh filename="package://phantomx_description/meshes/Bicep.stl" scale="0.01 0.01 0.01"/>
      </geometry>
    </collision>
    <visual>
      <origin rpy="1.5707963 0  0.0" xyz="-0.0 -0.0 0.0"/>
      <geometry>
        <mesh filename="package://phantomx_description/meshes/Bicep.stl" scale="0.01 0.01 0.01"/>
      </geometry>
      <material name="black"/>
    </visual>
    <inertial>
      <origin rpy="0 0 0" xyz="0 0 0"/>
      <mass value="0.1"/>
      <inertia ixx="0.1" ixy="0.0" ixz="0.0" iyy="0.1" iyz="0.0" izz="0.1"/>
    </inertial>
  </link>
  <joint name="arm_wrist_flex_joint" type="revolute">
    <parent link="link4"/>
    <child link="link5"/>
    <origin rpy="0 0 0" xyz="0 0. 0.106"/>
    <limit effort="10.0" lower="-1.72787593" upper="1.72787593" velocity="2"/>
    <axis xyz="0 1 0"/>
    <dynamics damping="0.7"/>
  </joint>
  <link name="link5">
    <collision>
      <origin rpy="-1.5707963 0  3.1415926" xyz="0.012 -0.0 0.035"/>
      <geometry>
        <mesh filename="package://phantomx_description/meshes/Wrist.stl" scale="0.01 0.01 0.01"/>
      </geometry>
    </collision>
    <visual>
      <origin rpy="-1.5707963 0  3.1415926" xyz="0.012 -0.0 0.035"/>
      <geometry>
        <mesh filename="package://phantomx_description/meshes/Wrist.stl" scale="0.01 0.01 0.01"/>
      </geometry>
      <material name="black"/>
    </visual>
    <inertial>
      <origin rpy="0 0 0" xyz="0 0 0"/>
      <mass value="0.1"/>
      <inertia ixx="0.1" ixy="0.0" ixz="0.0" iyy="0.1" iyz="0.0" izz="0.1"/>
    </inertial>
  </link>
  <joint name="joint5" type="fixed">
    <parent link="link5"/>
    <child link="link6"/>
    <origin rpy="0 0 0" xyz="0 0. 0.075"/>
    <!--axis xyz="0 0 1"/>
    <dynamics damping="0.7" /-->
  </joint>
  <link name="link6">
    <collision>
      <origin rpy="-0.0 0  1.5707963" xyz="-0.013 -0.011 -0.0035"/>
      <geometry>
        <mesh filename="package://phantomx_description/meshes/Guide_Rail_Fixed.stl" scale="0.01 0.01 0.01"/>
      </geometry>
    </collision>
    <visual>
      <origin rpy="-0.0 0  1.5707963" xyz="-0.013 -0.011 -0.0035"/>
      <geometry>
        <mesh filename="package://phantomx_description/meshes/Guide_Rail_Fixed.stl" scale="0.01 0.01 0.01"/>
      </geometry>
      <material name="black"/>
    </visual>
    <inertial>
      <origin rpy="0 0 0" xyz="0.0 0.0 0"/>
      <mass value="0.1"/>
      <inertia ixx="0.1" ixy="0.0" ixz="0.0" iyy="0.1" iyz="0.0" izz="0.1"/>
    </inertial>
  </link>
  <joint name="gripper_joint" type="prismatic">
    <axis xyz="0 1 0"/>
    <origin rpy="0 0 0" xyz="0 0.05 0.0105"/>
    <limit effort="10.0" lower="-0.025" upper="0.025" velocity="0.2"/>
    <dynamics damping="1000.0"/>
    <parent link="link6"/>
    <child link="finger1_link"/>
  </joint>
  <link name="finger1_link">
    <collision>
      <origin rpy="0 0 -1.5707963" xyz="0 0.0 0.0"/>
      <geometry>
        <mesh filename="package://phantomx_description/meshes/finger.stl" scale="0.01 0.01 0.01"/>
      </geometry>
    </collision>
    <visual>
      <origin rpy="0 0 -1.5707963" xyz="0 0.0 0.0"/>
      <geometry>
        <mesh filename="package://phantomx_description/meshes/finger.stl" scale="0.01 0.01 0.01"/>
      </geometry>
      <material name="black"/>
    </visual>
    <inertial>
      <mass value="8e-2"/>
      <origin rpy="0 0 0" xyz="0 0 0"/>
      <inertia ixx="1e-3" ixy="0" ixz="0" iyy="1e-3" iyz="0" izz="1e-3"/>
    </inertial>
  </link>
  <joint name="gripper_passive_joint" type="fixed">
    <axis xyz="0 -1 0"/>
    <origin rpy="0 0 0" xyz="0 -0.05 0.0105"/>
    <!--limit effort="10.0" lower="-0.025" upper="0.025" velocity="0.2"/>
      <dynamics damping="1000.0"/-->
    <parent link="link6"/>
    <child link="finger2_link"/>
    <!--mimic joint="gripper_joint" multiplier="-1" offset="0"/-->
  </joint>
  <link name="finger2_link">
    <collision>
      <origin rpy="0 0 1.5707963" xyz="0 0.0 0.0"/>
      <geometry>
        <mesh filename="package://phantomx_description/meshes/finger.stl" scale="0.01 0.01 0.01"/>
      </geometry>
    </collision>
    <visual>
      <origin rpy="0 0 1.5707963" xyz="0 0.0 0.0"/>
      <geometry>
        <mesh filename="package://phantomx_description/meshes/finger.stl" scale="0.01 0.01 0.01"/>
      </geometry>
      <material name="black"/>
    </visual>
    <inertial>
      <mass value="8e-2"/>
      <origin rpy="0 0 0" xyz="0 0 0"/>
      <inertia ixx="1e-3" ixy="0" ixz="0" iyy="1e-3" iyz="0" izz="1e-3"/>
    </inertial>
  </link>
  <transmission name="joint1_trans" type="pr2_mechanism_model/SimpleTransmission">
    <type>transmission_interface/SimpleTransmission</type>
    <actuator name="motor1">
      <hardwareInterface>EffortJointInterface</hardwareInterface>
      <mechanicalReduction>1</mechanicalReduction>
    </actuator>
    <joint name="arm_shoulder_pan_joint"/>
  </transmission>
  <transmission name="joint2_trans" type="pr2_mechanism_model/SimpleTransmission">
    <type>transmission_interface/SimpleTransmission</type>
    <actuator name="motor2">
      <hardwareInterface>EffortJointInterface</hardwareInterface>
      <mechanicalReduction>1</mechanicalReduction>
    </actuator>
    <joint name="arm_shoulder_lift_joint"/>
  </transmission>
  <transmission name="joint3_trans" type="pr2_mechanism_model/SimpleTransmission">
    <type>transmission_interface/SimpleTransmission</type>
    <actuator name="motor3">
      <hardwareInterface>EffortJointInterface</hardwareInterface>
      <mechanicalReduction>1</mechanicalReduction>
    </actuator>
    <joint name="arm_elbow_flex_joint"/>
  </transmission>
  <transmission name="joint4_trans" type="pr2_mechanism_model/SimpleTransmission">
    <type>transmission_interface/SimpleTransmission</type>
    <actuator name="motor4">
      <hardwareInterface>EffortJointInterface</hardwareInterface>
      <mechanicalReduction>1</mechanicalReduction>
    </actuator>
    <joint name="arm_wrist_flex_joint"/>
  </transmission>
  <transmission name="joint_gripper_trans" type="pr2_mechanism_model/SimpleTransmission">
    <type>transmission_interface/SimpleTransmission</type>
    <actuator name="motor8">
      <hardwareInterface>PositionJointInterface</hardwareInterface>
      <mechanicalReduction>1</mechanicalReduction>
    </actuator>
    <joint name="gripper_joint"/>
    <mechanicalReduction>1.0</mechanicalReduction>
  </transmission>
  <link name="base_footprint"/>
  <joint name="base_joint" type="fixed">
    <origin rpy="0 0 0" xyz="0 0 0.0102"/>
    <parent link="base_footprint"/>
    <child link="base_link"/>
  </joint>
  <link name="base_link">
    <visual>
      <geometry>
        <!-- new mesh -->
        <mesh filename="package://NonA_kobuki_description/meshes/main_body.dae"/>
      </geometry>
      <origin rpy="0 0 0" xyz="0.001 0 0.05199"/>
    </visual>
    <collision>
      <geometry>
        <cylinder length="0.10938" radius="0.176"/>
      </geometry>
      <origin rpy="0 0 0" xyz="0.0 0 0.05949"/>
    </collision>
    <inertial>
      <mass value="2.4"/>
      <!-- 2.4/2.6 kg for small/big battery pack -->
      <origin xyz="0 0 0"/>
      <inertia ixx="0.0001" ixy="0.0" ixz="0.0" iyy="0.0001" iyz="0.0" izz="0.0001"/>
    </inertial>
  </link>
  <joint name="laser_joint" type="fixed">
    <parent link="base_link"/>
    <child link="laser"/>
    <origin rpy="0 0 0" xyz="0.11 0.0 0.225"/>
  </joint>
  <link name="laser">
    <visual>
      <geometry>
        <mesh filename="package://NonA_kobuki_description/meshes/hokuyo_utm_30lx.dae" scale="0.7 0.7 0.7"/>
        <!--mesh filename="package://NonA_kobuki_description/meshes/hokuyo.dae"/-->
      </geometry>
      <origin rpy="0 0 1.57079632679" xyz="0 0 0"/>
    </visual>
    <inertial>
      <mass value="0.01"/>
      <origin xyz="0 0 0"/>
      <inertia ixx="0.001" ixy="0.0" ixz="0.0" iyy="0.001" iyz="0.0" izz="0.001"/>
    </inertial>
  </link>
  <joint name="wheel_left_joint" type="fixed">
    <parent link="base_link"/>
    <child link="wheel_left_link"/>
    <origin rpy="-1.57079632679 0 0" xyz="0.00 0.115 0.0250"/>
    <axis xyz="0 0 1"/>
  </joint>
  <link name="wheel_left_link">
    <visual>
      <geometry>
        <mesh filename="package://NonA_kobuki_description/meshes/wheel.dae"/>
      </geometry>
      <origin rpy="0 0 0" xyz="0 0 0"/>
    </visual>
    <collision>
      <geometry>
        <cylinder length="0.0206" radius="0.0352"/>
      </geometry>
      <origin rpy="0 0 0" xyz="0 0 0"/>
    </collision>
    <inertial>
      <mass value="0.01"/>
      <origin xyz="0 0 0"/>
      <inertia ixx="0.001" ixy="0.0" ixz="0.0" iyy="0.001" iyz="0.0" izz="0.001"/>
    </inertial>
  </link>
  <joint name="wheel_right_joint" type="fixed">
    <parent link="base_link"/>
    <child link="wheel_right_link"/>
    <origin rpy="-1.57079632679 0 0" xyz="0.00 -0.115 0.0250"/>
    <axis xyz="0 0 1"/>
  </joint>
  <link name="wheel_right_link">
    <visual>
      <geometry>
        <mesh filename="package://NonA_kobuki_description/meshes/wheel.dae"/>
      </geometry>
      <origin rpy="0 0 0" xyz="0 0 0"/>
    </visual>
    <collision>
      <geometry>
        <cylinder length="0.0206" radius="0.0350"/>
      </geometry>
      <origin rpy="0 0 0" xyz="0 0 0"/>
    </collision>
    <inertial>
      <mass value="0.01"/>
      <origin xyz="0 0 0"/>
      <inertia ixx="0.001" ixy="0.0" ixz="0.0" iyy="0.001" iyz="0.0" izz="0.001"/>
    </inertial>
  </link>
  <joint name="caster_front_joint" type="fixed">
    <parent link="base_link"/>
    <child link="caster_front_link"/>
    <origin rpy="-1.57079632679 0 0" xyz="0.115 0.0 0.007"/>
  </joint>
  <link name="caster_front_link">
    <collision>
      <geometry>
        <cylinder length="0.0176" radius="0.017"/>
      </geometry>
      <origin rpy="0 0 0" xyz="0 0 0"/>
    </collision>
    <inertial>
      <mass value="0.01"/>
      <origin xyz="0 0 0"/>
      <inertia ixx="0.001" ixy="0.0" ixz="0.0" iyy="0.001" iyz="0.0" izz="0.001"/>
    </inertial>
  </link>
  <joint name="caster_back_joint" type="fixed">
    <parent link="base_link"/>
    <child link="caster_back_link"/>
    <origin rpy="-1.57079632679 0 0" xyz="-0.135 0.0 0.009"/>
  </joint>
  <link name="caster_back_link">
    <collision>
      <geometry>
        <cylinder length="0.0176" radius="0.017"/>
      </geometry>
      <origin rpy="0 0 0" xyz="0 0 0"/>
    </collision>
    <inertial>
      <mass value="0.01"/>
      <origin xyz="0 0 0"/>
      <inertia ixx="0.001" ixy="0.0" ixz="0.0" iyy="0.001" iyz="0.0" izz="0.001"/>
    </inertial>
  </link>
  <joint name="gyro_joint" type="fixed">
    <axis xyz="0 1 0"/>
    <origin rpy="0 0 0" xyz="0.056 0.062 0.0202"/>
    <parent link="base_link"/>
    <child link="gyro_link"/>
  </joint>
  <link name="gyro_link">
    <inertial>
      <mass value="0.001"/>
      <origin rpy="0 0 0" xyz="0 0 0"/>
      <inertia ixx="0.0001" ixy="0" ixz="0" iyy="0.000001" iyz="0" izz="0.0001"/>
    </inertial>
  </link>
  <joint name="cliff_sensor_left_joint" type="fixed">
    <origin rpy="0 1.57079632679 0" xyz="0.08734 0.13601 0.0214"/>
    <parent link="base_link"/>
    <child link="cliff_sensor_left_link"/>
  </joint>
  <link name="cliff_sensor_left_link">
    <inertial>
      <mass value="0.0001"/>
      <origin xyz="0 0 0"/>
      <inertia ixx="0.0001" ixy="0.0" ixz="0.0" iyy="0.0001" iyz="0.0" izz="0.0001"/>
    </inertial>
  </link>
  <joint name="cliff_sensor_right_joint" type="fixed">
    <origin rpy="0 1.57079632679 0" xyz="0.085 -0.13601 0.0214"/>
    <parent link="base_link"/>
    <child link="cliff_sensor_right_link"/>
  </joint>
  <link name="cliff_sensor_right_link">
    <inertial>
      <mass value="0.0001"/>
      <origin xyz="0 0 0"/>
      <inertia ixx="0.0001" ixy="0.0" ixz="0.0" iyy="0.0001" iyz="0.0" izz="0.0001"/>
    </inertial>
  </link>
  <joint name="cliff_sensor_front_joint" type="fixed">
    <origin rpy="0 1.57079632679 0" xyz="0.156 0.00 0.0214"/>
    <parent link="base_link"/>
    <child link="cliff_sensor_front_link"/>
  </joint>
  <link name="cliff_sensor_front_link">
    <inertial>
      <mass value="0.0001"/>
      <origin xyz="0 0 0"/>
      <inertia ixx="0.0001" ixy="0.0" ixz="0.0" iyy="0.0001" iyz="0.0" izz="0.0001"/>
    </inertial>
  </link>
  <joint name="pole_bottom_0_joint" type="fixed">
    <origin rpy="0 0 0" xyz="0.12 0.082 0.1028"/>
    <parent link="base_link"/>
    <child link="pole_bottom_0_link"/>
  </joint>
  <link name="pole_bottom_0_link">
    <visual>
      <origin rpy="0 0 0" xyz="0 0 0"/>
      <geometry>
        <mesh filename="package://NonA_turtlebot_description/meshes/stacks/hexagons/pole_bottom.dae"/>
      </geometry>
    </visual>
    <collision>
      <origin rpy="0 0 0" xyz="0 0 0"/>
      <geometry>
        <cylinder length="0.0492" radius=".006"/>
      </geometry>
    </collision>
    <inertial>
      <mass value="0.001"/>
      <origin rpy="0 0 0" xyz="0 0 0"/>
      <inertia ixx="0.0001" ixy="0.0" ixz="0.0" iyy="0.0001" iyz="0.0" izz="0.0001"/>
    </inertial>
  </link>
  <joint name="pole_bottom_1_joint" type="fixed">
    <origin rpy="0 0 0" xyz="0.055 0.12 0.1028"/>
    <parent link="base_link"/>
    <child link="pole_bottom_1_link"/>
  </joint>
  <link name="pole_bottom_1_link">
    <visual>
      <origin rpy="0 0 0" xyz="0 0 0"/>
      <geometry>
        <mesh filename="package://NonA_turtlebot_description/meshes/stacks/hexagons/pole_bottom.dae"/>
      </geometry>
    </visual>
    <collision>
      <origin rpy="0 0 0" xyz="0 0 0"/>
      <geometry>
        <cylinder length="0.0492" radius=".006"/>
      </geometry>
    </collision>
    <inertial>
      <mass value="0.001"/>
      <origin rpy="0 0 0" xyz="0 0 0"/>
      <inertia ixx="0.0001" ixy="0.0" ixz="0.0" iyy="0.0001" iyz="0.0" izz="0.0001"/>
    </inertial>
  </link>
  <joint name="pole_bottom_2_joint" type="fixed">
    <origin rpy="0 0 0" xyz="-0.055 0.12 0.1028"/>
    <parent link="base_link"/>
    <child link="pole_bottom_2_link"/>
  </joint>
  <link name="pole_bottom_2_link">
    <visual>
      <origin rpy="0 0 0" xyz="0 0 0"/>
      <geometry>
        <mesh filename="package://NonA_turtlebot_description/meshes/stacks/hexagons/pole_bottom.dae"/>
      </geometry>
    </visual>
    <collision>
      <origin rpy="0 0 0" xyz="0 0 0"/>
      <geometry>
        <cylinder length="0.0492" radius=".006"/>
      </geometry>
    </collision>
    <inertial>
      <mass value="0.001"/>
      <origin rpy="0 0 0" xyz="0 0 0"/>
      <inertia ixx="0.0001" ixy="0.0" ixz="0.0" iyy="0.0001" iyz="0.0" izz="0.0001"/>
    </inertial>
  </link>
  <joint name="pole_bottom_3_joint" type="fixed">
    <origin rpy="0 0 0" xyz="0.12 -0.082 0.1028"/>
    <parent link="base_link"/>
    <child link="pole_bottom_3_link"/>
  </joint>
  <link name="pole_bottom_3_link">
    <visual>
      <origin rpy="0 0 0" xyz="0 0 0"/>
      <geometry>
        <mesh filename="package://NonA_turtlebot_description/meshes/stacks/hexagons/pole_bottom.dae"/>
      </geometry>
    </visual>
    <collision>
      <origin rpy="0 0 0" xyz="0 0 0"/>
      <geometry>
        <cylinder length="0.0492" radius=".006"/>
      </geometry>
    </collision>
    <inertial>
      <mass value="0.001"/>
      <origin rpy="0 0 0" xyz="0 0 0"/>
      <inertia ixx="0.0001" ixy="0.0" ixz="0.0" iyy="0.0001" iyz="0.0" izz="0.0001"/>
    </inertial>
  </link>
  <joint name="pole_bottom_4_joint" type="fixed">
    <origin rpy="0 0 0" xyz="0.055 -0.12 0.1028"/>
    <parent link="base_link"/>
    <child link="pole_bottom_4_link"/>
  </joint>
  <link name="pole_bottom_4_link">
    <visual>
      <origin rpy="0 0 0" xyz="0 0 0"/>
      <geometry>
        <mesh filename="package://NonA_turtlebot_description/meshes/stacks/hexagons/pole_bottom.dae"/>
      </geometry>
    </visual>
    <collision>
      <origin rpy="0 0 0" xyz="0 0 0"/>
      <geometry>
        <cylinder length="0.0492" radius=".006"/>
      </geometry>
    </collision>
    <inertial>
      <mass value="0.001"/>
      <origin rpy="0 0 0" xyz="0 0 0"/>
      <inertia ixx="0.0001" ixy="0.0" ixz="0.0" iyy="0.0001" iyz="0.0" izz="0.0001"/>
    </inertial>
  </link>
  <joint name="pole_bottom_5_joint" type="fixed">
    <origin rpy="0 0 0" xyz="-0.055 -0.12 0.1028"/>
    <parent link="base_link"/>
    <child link="pole_bottom_5_link"/>
  </joint>
  <link name="pole_bottom_5_link">
    <visual>
      <origin rpy="0 0 0" xyz="0 0 0"/>
      <geometry>
        <mesh filename="package://NonA_turtlebot_description/meshes/stacks/hexagons/pole_bottom.dae"/>
      </geometry>
    </visual>
    <collision>
      <origin rpy="0 0 0" xyz="0 0 0"/>
      <geometry>
        <cylinder length="0.0492" radius=".006"/>
      </geometry>
    </collision>
    <inertial>
      <mass value="0.001"/>
      <origin rpy="0 0 0" xyz="0 0 0"/>
      <inertia ixx="0.0001" ixy="0.0" ixz="0.0" iyy="0.0001" iyz="0.0" izz="0.0001"/>
    </inertial>
  </link>
  <joint name="plate_bottom_joint" type="fixed">
    <origin rpy="0 0 0" xyz="0.02364 0.0 0.1306"/>
    <parent link="base_link"/>
    <child link="plate_bottom_link"/>
  </joint>
  <link name="plate_bottom_link">
    <visual>
      <origin rpy="0 0 0" xyz="0 0 0"/>
      <geometry>
        <mesh filename="package://NonA_turtlebot_description/meshes/stacks/hexagons/plate_bottom.dae"/>
      </geometry>
    </visual>
    <collision>
      <origin rpy="0 0 0" xyz="0 0 0"/>
      <geometry>
        <box size="0.26727 0.340 0.006"/>
      </geometry>
    </collision>
    <inertial>
      <mass value="0.01"/>
      <origin xyz="0 0 0"/>
      <inertia ixx="0.01" ixy="0.0" ixz="0.0" iyy="0.01" iyz="0.0" izz="0.01"/>
    </inertial>
  </link>
  <joint name="pole_middle_0_joint" type="fixed">
    <origin rpy="0 0 0" xyz="0.0381 0.1505 0.164"/>
    <parent link="base_link"/>
    <child link="pole_middle_0_link"/>
  </joint>
  <link name="pole_middle_0_link">
    <visual>
      <origin rpy="0 3.14159265359 0" xyz="0 0 0"/>
      <geometry>
        <mesh filename="package://NonA_turtlebot_description/meshes/stacks/hexagons/pole_middle.dae"/>
      </geometry>
    </visual>
    <collision>
      <origin rpy="0 0 0" xyz="0 0 0"/>
      <geometry>
        <cylinder length="0.0608" radius=".006"/>
      </geometry>
    </collision>
    <inertial>
      <mass value="0.001"/>
      <origin xyz="0 0 0"/>
      <inertia ixx="0.0001" ixy="0.0" ixz="0.0" iyy="0.0001" iyz="0.0" izz="0.0001"/>
    </inertial>
  </link>
  <joint name="pole_middle_1_joint" type="fixed">
    <origin rpy="0 0 0" xyz="0.0381 -0.1505 0.164"/>
    <parent link="base_link"/>
    <child link="pole_middle_1_link"/>
  </joint>
  <link name="pole_middle_1_link">
    <visual>
      <origin rpy="0 3.14159265359 0" xyz="0 0 0"/>
      <geometry>
        <mesh filename="package://NonA_turtlebot_description/meshes/stacks/hexagons/pole_middle.dae"/>
      </geometry>
    </visual>
    <collision>
      <origin rpy="0 0 0" xyz="0 0 0"/>
      <geometry>
        <cylinder length="0.0608" radius=".006"/>
      </geometry>
    </collision>
    <inertial>
      <mass value="0.001"/>
      <origin xyz="0 0 0"/>
      <inertia ixx="0.0001" ixy="0.0" ixz="0.0" iyy="0.0001" iyz="0.0" izz="0.0001"/>
    </inertial>
  </link>
  <joint name="pole_middle_2_joint" type="fixed">
    <origin rpy="0 0 0" xyz="-0.0381 0.1505 0.164"/>
    <parent link="base_link"/>
    <child link="pole_middle_2_link"/>
  </joint>
  <link name="pole_middle_2_link">
    <visual>
      <origin rpy="0 3.14159265359 0" xyz="0 0 0"/>
      <geometry>
        <mesh filename="package://NonA_turtlebot_description/meshes/stacks/hexagons/pole_middle.dae"/>
      </geometry>
    </visual>
    <collision>
      <origin rpy="0 0 0" xyz="0 0 0"/>
      <geometry>
        <cylinder length="0.0608" radius=".006"/>
      </geometry>
    </collision>
    <inertial>
      <mass value="0.001"/>
      <origin xyz="0 0 0"/>
      <inertia ixx="0.0001" ixy="0.0" ixz="0.0" iyy="0.0001" iyz="0.0" izz="0.0001"/>
    </inertial>
  </link>
  <joint name="pole_middle_3_joint" type="fixed">
    <origin rpy="0 0 0" xyz="-0.0381 -0.1505 0.164"/>
    <parent link="base_link"/>
    <child link="pole_middle_3_link"/>
  </joint>
  <link name="pole_middle_3_link">
    <visual>
      <origin rpy="0 3.14159265359 0" xyz="0 0 0"/>
      <geometry>
        <mesh filename="package://NonA_turtlebot_description/meshes/stacks/hexagons/pole_middle.dae"/>
      </geometry>
    </visual>
    <collision>
      <origin rpy="0 0 0" xyz="0 0 0"/>
      <geometry>
        <cylinder length="0.0608" radius=".006"/>
      </geometry>
    </collision>
    <inertial>
      <mass value="0.001"/>
      <origin xyz="0 0 0"/>
      <inertia ixx="0.0001" ixy="0.0" ixz="0.0" iyy="0.0001" iyz="0.0" izz="0.0001"/>
    </inertial>
  </link>
  <joint name="plate_middle_joint" type="fixed">
    <origin rpy="0 0 0" xyz="-0.01364 0.0 0.1874"/>
    <parent link="base_link"/>
    <child link="plate_middle_link"/>
  </joint>
  <link name="plate_middle_link">
    <visual>
      <origin rpy="0 0 0" xyz="0 0 0"/>
      <geometry>
        <mesh filename="package://NonA_turtlebot_description/meshes/stacks/hexagons/plate_middle.dae"/>
      </geometry>
    </visual>
    <collision>
      <origin rpy="0 0 0" xyz="0.0 0.0 0.0"/>
      <geometry>
        <box size="0.28727 0.340 0.006"/>
      </geometry>
    </collision>
    <inertial>
      <mass value="0.01"/>
      <origin xyz="0 0 0"/>
      <inertia ixx="0.01" ixy="0.0" ixz="0.0" iyy="0.01" iyz="0.0" izz="0.01"/>
    </inertial>
  </link>
  <joint name="pole_top_0_joint" type="fixed">
    <origin rpy="0 0 0" xyz="0.0381 0.1505 0.292"/>
    <parent link="base_link"/>
    <child link="pole_top_0_link"/>
  </joint>
  <link name="pole_top_0_link">
    <visual>
      <origin rpy="0 0 0" xyz=" 0 0 0"/>
      <geometry>
        <mesh filename="package://NonA_turtlebot_description/meshes/stacks/hexagons/pole_top.dae"/>
      </geometry>
    </visual>
    <collision>
      <origin rpy="0 0 0" xyz="0 0 0"/>
      <geometry>
        <cylinder length="0.2032" radius=".006"/>
      </geometry>
    </collision>
    <inertial>
      <mass value="0.001"/>
      <origin xyz="0 0 0"/>
      <inertia ixx="0.0001" ixy="0.0" ixz="0.0" iyy="0.0001" iyz="0.0" izz="0.0001"/>
    </inertial>
  </link>
  <joint name="pole_top_1_joint" type="fixed">
    <origin rpy="0 0 0" xyz="0.0381 -0.1505 0.292"/>
    <parent link="base_link"/>
    <child link="pole_top_1_link"/>
  </joint>
  <link name="pole_top_1_link">
    <visual>
      <origin rpy="0 0 0" xyz=" 0 0 0"/>
      <geometry>
        <mesh filename="package://NonA_turtlebot_description/meshes/stacks/hexagons/pole_top.dae"/>
      </geometry>
    </visual>
    <collision>
      <origin rpy="0 0 0" xyz="0 0 0"/>
      <geometry>
        <cylinder length="0.2032" radius=".006"/>
      </geometry>
    </collision>
    <inertial>
      <mass value="0.001"/>
      <origin xyz="0 0 0"/>
      <inertia ixx="0.0001" ixy="0.0" ixz="0.0" iyy="0.0001" iyz="0.0" izz="0.0001"/>
    </inertial>
  </link>
  <joint name="pole_top_2_joint" type="fixed">
    <origin rpy="0 0 0" xyz="-0.0381 0.1505 0.292"/>
    <parent link="base_link"/>
    <child link="pole_top_2_link"/>
  </joint>
  <link name="pole_top_2_link">
    <visual>
      <origin rpy="0 0 0" xyz=" 0 0 0"/>
      <geometry>
        <mesh filename="package://NonA_turtlebot_description/meshes/stacks/hexagons/pole_top.dae"/>
      </geometry>
    </visual>
    <collision>
      <origin rpy="0 0 0" xyz="0 0 0"/>
      <geometry>
        <cylinder length="0.2032" radius=".006"/>
      </geometry>
    </collision>
    <inertial>
      <mass value="0.001"/>
      <origin xyz="0 0 0"/>
      <inertia ixx="0.0001" ixy="0.0" ixz="0.0" iyy="0.0001" iyz="0.0" izz="0.0001"/>
    </inertial>
  </link>
  <joint name="pole_top_3_joint" type="fixed">
    <origin rpy="0 0 0" xyz="-0.0381 -0.1505 0.292"/>
    <parent link="base_link"/>
    <child link="pole_top_3_link"/>
  </joint>
  <link name="pole_top_3_link">
    <visual>
      <origin rpy="0 0 0" xyz=" 0 0 0"/>
      <geometry>
        <mesh filename="package://NonA_turtlebot_description/meshes/stacks/hexagons/pole_top.dae"/>
      </geometry>
    </visual>
    <collision>
      <origin rpy="0 0 0" xyz="0 0 0"/>
      <geometry>
        <cylinder length="0.2032" radius=".006"/>
      </geometry>
    </collision>
    <inertial>
      <mass value="0.001"/>
      <origin xyz="0 0 0"/>
      <inertia ixx="0.0001" ixy="0.0" ixz="0.0" iyy="0.0001" iyz="0.0" izz="0.0001"/>
    </inertial>
  </link>
  <joint name="pole_kinect_0_joint" type="fixed">
    <origin rpy="0 0 0" xyz="-0.1024 0.098 0.2372"/>
    <parent link="base_link"/>
    <child link="pole_kinect_0_link"/>
  </joint>
  <link name="pole_kinect_0_link">
    <visual>
      <origin rpy="0 0 0" xyz="0 0 0"/>
      <!--         <origin xyz="0 0 0" rpy="${-M_PI/2} ${M_PI} 0"/> -->
      <geometry>
        <mesh filename="package://NonA_turtlebot_description/meshes/stacks/hexagons/pole_kinect.dae"/>
      </geometry>
    </visual>
    <collision>
      <origin rpy="0 0 0" xyz="0 0 0"/>
      <geometry>
        <cylinder length="0.0936" radius="0.006"/>
      </geometry>
    </collision>
    <inertial>
      <mass value="0.001"/>
      <origin xyz="0 0 0"/>
      <inertia ixx="0.0001" ixy="0.0" ixz="0.0" iyy="0.0001" iyz="0.0" izz="0.0001"/>
    </inertial>
  </link>
  <joint name="pole_kinect_1_joint" type="fixed">
    <origin rpy="0 0 0" xyz="-0.1024 -0.098 0.2372"/>
    <parent link="base_link"/>
    <child link="pole_kinect_1_link"/>
  </joint>
  <link name="pole_kinect_1_link">
    <visual>
      <origin rpy="0 0 0" xyz="0 0 0"/>
      <!--         <origin xyz="0 0 0" rpy="${-M_PI/2} ${M_PI} 0"/> -->
      <geometry>
        <mesh filename="package://NonA_turtlebot_description/meshes/stacks/hexagons/pole_kinect.dae"/>
      </geometry>
    </visual>
    <collision>
      <origin rpy="0 0 0" xyz="0 0 0"/>
      <geometry>
        <cylinder length="0.0936" radius="0.006"/>
      </geometry>
    </collision>
    <inertial>
      <mass value="0.001"/>
      <origin xyz="0 0 0"/>
      <inertia ixx="0.0001" ixy="0.0" ixz="0.0" iyy="0.0001" iyz="0.0" izz="0.0001"/>
    </inertial>
  </link>
  <joint name="plate_top_joint" type="fixed">
    <origin rpy="0 0 0" xyz="-0.01364 0.0  0.3966"/>
    <parent link="base_link"/>
    <child link="plate_top_link"/>
  </joint>
  <link name="plate_top_link">
    <visual>
      <origin rpy="0 0 0" xyz="0 0 0"/>
      <geometry>
        <mesh filename="package://NonA_turtlebot_description/meshes/stacks/hexagons/plate_top.dae"/>
      </geometry>
    </visual>
    <collision>
      <origin rpy="0 0 0" xyz="0 0 0"/>
      <geometry>
        <box size="0.28727 0.340 0.006"/>
      </geometry>
    </collision>
    <inertial>
      <mass value="0.01"/>
      <origin xyz="0 0 0"/>
      <inertia ixx="0.01" ixy="0.0" ixz="0.0" iyy="0.01" iyz="0.0" izz="0.01"/>
    </inertial>
  </link>
  <sensor_kinect parent="base_link"/>
</robot>
