<?xml version="1.0" ?>
<!-- =================================================================================== -->
<!-- |    This document was autogenerated by xacro from phantomx.xacro                 | -->
<!-- |    EDITING THIS FILE BY HAND IS NOT RECOMMENDED                                 | -->
<!-- =================================================================================== -->
<!-- Revolute-Revolute Manipulator -->
<robot name="phantomx" xmlns:xacro="http://www.ros.org/wiki/xacro">
  <!-- Constants for robot dimensions -->
  <!-- Square dimensions (widthxwidth) of beams -->
  <!-- Link 1 -->
  <!-- Link 2 -->
  <!-- Link 3 -->
  <!-- Link 4 -->
  <!-- Link 5 -->
  <!-- Link 6 -->
  <!-- Size of square 'camera' box -->
  <!-- Space btw top of beam and the each joint -->
  <!-- for zooming the meshes -->
  <!-- Import all Gazebo-customization elements, including Gazebo colors -->
  <gazebo>
    <plugin filename="libgazebo_ros_control.so" name="gazebo_ros_control">
      <robotParam>/robot_description</robotParam>
    </plugin>
  </gazebo>
  <gazebo reference="link1">
    <material>Gazebo/Black</material>
  </gazebo>
  <gazebo reference="link2">
    <mu1>0.2</mu1>
    <mu2>0.2</mu2>
    <material>Gazebo/Orange</material>
  </gazebo>
  <gazebo reference="link3">
    <mu1>0.2</mu1>
    <mu2>0.2</mu2>
    <material>Gazebo/Green</material>
  </gazebo>
  <gazebo reference="link4">
    <mu1>0.2</mu1>
    <mu2>0.2</mu2>
    <material>Gazebo/Orange</material>
  </gazebo>
  <gazebo reference="link5">
    <mu1>0.2</mu1>
    <mu2>0.2</mu2>
    <material>Gazebo/Blue</material>
  </gazebo>
  <gazebo reference="link6">
    <mu1>0.2</mu1>
    <mu2>0.2</mu2>
    <material>Gazebo/Black</material>
  </gazebo>
  <gazebo reference="camera_link">
    <mu1>0.2</mu1>
    <mu2>0.2</mu2>
    <material>Gazebo/Red</material>
  </gazebo>
  <!-- Import Rviz colors -->
  <material name="black">
    <color rgba="0.15 0.15 0.15 1.0"/>
  </material>
  <material name="blue">
    <color rgba="0.0 0.0 0.8 1.0"/>
  </material>
  <material name="green">
    <color rgba="0.0 0.8 0.0 1.0"/>
  </material>
  <material name="grey">
    <color rgba="0.2 0.2 0.2 1.0"/>
  </material>
  <material name="orange">
    <color rgba="1.0 0.423529411765 0.0392156862745 1.0"/>
  </material>
  <material name="brown">
    <color rgba="0.870588235294 0.811764705882 0.764705882353 1.0"/>
  </material>
  <material name="red">
    <color rgba="0.8 0.0 0.0 1.0"/>
  </material>
  <material name="white">
    <color rgba="1.0 1.0 1.0 1.0"/>
  </material>
  <!-- Used for fixing robot to Gazebo 'base_link' -->
  <link name="world"/>
  <joint name="fixed" type="fixed">
    <parent link="world"/>
    <child link="link1"/>
  </joint>
  <!-- Base Link -->
  <link name="link1">
    <collision>
      <origin rpy="0 0 0" xyz="0 0 0.0"/>
      <geometry>
        <box size="0.08 0.08 0.086"/>
      </geometry>
    </collision>
    <visual>
      <origin rpy="-0.0 0  0.0" xyz="-0.1 -0.132 0.0"/>
      <geometry>
        <mesh filename="package://phantomx_description/meshes/Base.stl" scale="0.01 0.01 0.01"/>
      </geometry>
      <material name="black"/>
    </visual>
    <inertial>
      <origin rpy="0 0 0" xyz="0 0 0"/>
      <mass value="1"/>
      <inertia ixx="1.0" ixy="0.0" ixz="0.0" iyy="1.0" iyz="0.0" izz="1.0"/>
    </inertial>
  </link>
  <joint name="joint1" type="continuous">
    <parent link="link1"/>
    <child link="link2"/>
    <origin rpy="0 0 0" xyz="0 0. 0.086"/>
    <axis xyz="0 0 1"/>
    <!--limit effort="30" velocity="1.0" lower="-3.1416" upper="3.1416" /-->
    <dynamics damping="0.7"/>
  </joint>
  <link name="link2">
    <collision>
      <origin rpy="0 0 0" xyz="0 0 0.0"/>
      <geometry>
        <box size="0.08 0.08 0.086"/>
      </geometry>
    </collision>
    <visual>
      <origin rpy="1.5707963 0  1.5707963" xyz="-0.0 -0.0 0.0"/>
      <geometry>
        <mesh filename="package://phantomx_description/meshes/Shoulder.stl" scale="0.01 0.01 0.01"/>
      </geometry>
      <material name="black"/>
    </visual>
    <inertial>
      <origin rpy="0 0 0" xyz="0 0 0"/>
      <mass value="1"/>
      <inertia ixx="1.0" ixy="0.0" ixz="0.0" iyy="1.0" iyz="0.0" izz="1.0"/>
    </inertial>
  </link>
  <joint name="joint2" type="continuous">
    <parent link="link2"/>
    <child link="link3"/>
    <origin rpy="0 0 0" xyz="0 0. 0.042"/>
    <axis xyz="1 0 0"/>
    <dynamics damping="0.7"/>
  </joint>
  <link name="link3">
    <collision>
      <origin rpy="0 0 0" xyz="0 0 0.0"/>
      <geometry>
        <box size="0.08 0.08 0.086"/>
      </geometry>
    </collision>
    <visual>
      <origin rpy="1.5707963 0  1.5707963" xyz="-0.0 -0.0 0.0"/>
      <geometry>
        <mesh filename="package://phantomx_description/meshes/Bicep.stl" scale="0.01 0.01 0.01"/>
      </geometry>
      <material name="black"/>
    </visual>
    <inertial>
      <origin rpy="0 0 0" xyz="0 0 0"/>
      <mass value="1"/>
      <inertia ixx="1.0" ixy="0.0" ixz="0.0" iyy="1.0" iyz="0.0" izz="1.0"/>
    </inertial>
  </link>
  <joint name="joint3" type="continuous">
    <parent link="link3"/>
    <child link="link4"/>
    <origin rpy="0 0 0" xyz="0 0. 0.106"/>
    <axis xyz="1 0 0"/>
    <dynamics damping="0.7"/>
  </joint>
  <link name="link4">
    <collision>
      <origin rpy="0 0 0" xyz="0 0 0.0"/>
      <geometry>
        <box size="0.08 0.08 0.086"/>
      </geometry>
    </collision>
    <visual>
      <origin rpy="1.5707963 0  1.5707963" xyz="-0.0 -0.0 0.0"/>
      <geometry>
        <mesh filename="package://phantomx_description/meshes/Bicep.stl" scale="0.01 0.01 0.01"/>
      </geometry>
      <material name="black"/>
    </visual>
    <inertial>
      <origin rpy="0 0 0" xyz="0 0 0"/>
      <mass value="1"/>
      <inertia ixx="1.0" ixy="0.0" ixz="0.0" iyy="1.0" iyz="0.0" izz="1.0"/>
    </inertial>
  </link>
  <joint name="joint4" type="continuous">
    <parent link="link4"/>
    <child link="link5"/>
    <origin rpy="0 0 0" xyz="0 0. 0.106"/>
    <axis xyz="1 0 0"/>
    <dynamics damping="0.7"/>
  </joint>
  <link name="link5">
    <collision>
      <origin rpy="0 0 0" xyz="0 0 0.0"/>
      <geometry>
        <box size="0.08 0.08 0.086"/>
      </geometry>
    </collision>
    <visual>
      <origin rpy="-1.5707963 0  1.5707963" xyz="-0.0 -0.012 0.0325"/>
      <geometry>
        <mesh filename="package://phantomx_description/meshes/Wrist.stl" scale="0.01 0.01 0.01"/>
      </geometry>
      <material name="black"/>
    </visual>
    <inertial>
      <origin rpy="0 0 0" xyz="0 0 0"/>
      <mass value="1"/>
      <inertia ixx="1.0" ixy="0.0" ixz="0.0" iyy="1.0" iyz="0.0" izz="1.0"/>
    </inertial>
  </link>
  <joint name="joint5" type="continuous">
    <parent link="link5"/>
    <child link="link6"/>
    <origin rpy="0 0 0" xyz="0 0. 0.065"/>
    <axis xyz="0 0 1"/>
    <dynamics damping="0.7"/>
  </joint>
  <link name="link6">
    <collision>
      <origin rpy="0 0 0" xyz="0 0 0.0"/>
      <geometry>
        <box size="0.08 0.08 0.086"/>
      </geometry>
    </collision>
    <visual>
      <origin rpy="-0.0 0  0.0" xyz="-0.016 -0.036 -0.0325"/>
      <geometry>
        <mesh filename="package://phantomx_description/meshes/PX-Gripper.stl" scale="0.01 0.01 0.01"/>
      </geometry>
      <material name="black"/>
    </visual>
    <inertial>
      <origin rpy="0 0 0" xyz="0 0 0"/>
      <mass value="1"/>
      <inertia ixx="1.0" ixy="0.0" ixz="0.0" iyy="1.0" iyz="0.0" izz="1.0"/>
    </inertial>
  </link>
  <transmission name="joint1_trans" type="pr2_mechanism_model/SimpleTransmission">
    <type>transmission_interface/SimpleTransmission</type>
    <actuator name="motor1">
      <hardwareInterface>EffortJointInterface</hardwareInterface>
      <mechanicalReduction>1</mechanicalReduction>
    </actuator>
    <joint name="joint1"/>
  </transmission>
  <transmission name="joint2_trans" type="pr2_mechanism_model/SimpleTransmission">
    <type>transmission_interface/SimpleTransmission</type>
    <actuator name="motor2">
      <hardwareInterface>EffortJointInterface</hardwareInterface>
      <mechanicalReduction>1</mechanicalReduction>
    </actuator>
    <joint name="joint2"/>
  </transmission>
  <transmission name="joint3_trans" type="pr2_mechanism_model/SimpleTransmission">
    <type>transmission_interface/SimpleTransmission</type>
    <actuator name="motor3">
      <hardwareInterface>EffortJointInterface</hardwareInterface>
      <mechanicalReduction>1</mechanicalReduction>
    </actuator>
    <joint name="joint3"/>
  </transmission>
  <transmission name="joint4_trans" type="pr2_mechanism_model/SimpleTransmission">
    <type>transmission_interface/SimpleTransmission</type>
    <actuator name="motor4">
      <hardwareInterface>EffortJointInterface</hardwareInterface>
      <mechanicalReduction>1</mechanicalReduction>
    </actuator>
    <joint name="joint4"/>
  </transmission>
  <transmission name="joint5_trans" type="pr2_mechanism_model/SimpleTransmission">
    <type>transmission_interface/SimpleTransmission</type>
    <actuator name="motor5">
      <hardwareInterface>EffortJointInterface</hardwareInterface>
      <mechanicalReduction>1</mechanicalReduction>
    </actuator>
    <joint name="joint5"/>
  </transmission>
</robot>
